INFO:root:Executed R('local({r <- getOption(\'repos\'); r[\'CRAN\'] <- \'http://cran.r-project.org\'; options(repos=r)})')
INFO:root:Executed R('load(\'../../instructor/assignments/hw3/hw3-tests.rda\')')
ERROR:root:(1 points) Checking R('all.equal(n.wr, sol$n.wr)')[0]
ERROR:root:... Expecting: True
ERROR:root:... But got:   Traceback error
ERROR:root:Got exception:
Traceback (most recent call last):
  File "c:\Users\User\Anaconda\lib\site-packages\gradebook\score.py", line 180, in check
    result = eval(command, g)
  File "<string>", line 1, in <module>
  File "c:\Users\User\Anaconda\lib\site-packages\rpy2\robjects\__init__.py", line 246, in __call__
    res = self.eval(p)
  File "c:\Users\User\Anaconda\lib\site-packages\rpy2\robjects\functions.py", line 166, in __call__
    return super(SignatureTranslatedFunction, self).__call__(*args, **kwargs)
  File "c:\Users\User\Anaconda\lib\site-packages\rpy2\robjects\functions.py", line 99, in __call__
    res = super(Function, self).__call__(*new_args, **new_kwargs)
RRuntimeError: Error in all.equal(n.wr, sol$n.wr) : object 'n.wr' not found

ERROR:root:Traceback (most recent call last):
  File "c:\Users\User\Anaconda\lib\site-packages\gradebook\score.py", line 180, in check
    result = eval(command, g)
  File "<string>", line 1, in <module>
  File "c:\Users\User\Anaconda\lib\site-packages\rpy2\robjects\__init__.py", line 246, in __call__
    res = self.eval(p)
  File "c:\Users\User\Anaconda\lib\site-packages\rpy2\robjects\functions.py", line 166, in __call__
    return super(SignatureTranslatedFunction, self).__call__(*args, **kwargs)
  File "c:\Users\User\Anaconda\lib\site-packages\rpy2\robjects\functions.py", line 99, in __call__
    res = super(Function, self).__call__(*new_args, **new_kwargs)
RRuntimeError: Error in all.equal(n.wr, sol$n.wr) : object 'n.wr' not found

Traceback (most recent call last):
  File "c:\Users\User\Anaconda\lib\site-packages\gradebook\score.py", line 180, in check
    result = eval(command, g)
  File "<string>", line 1, in <module>
  File "c:\Users\User\Anaconda\lib\site-packages\rpy2\robjects\__init__.py", line 246, in __call__
    res = self.eval(p)
  File "c:\Users\User\Anaconda\lib\site-packages\rpy2\robjects\functions.py", line 166, in __call__
    return super(SignatureTranslatedFunction, self).__call__(*args, **kwargs)
  File "c:\Users\User\Anaconda\lib\site-packages\rpy2\robjects\functions.py", line 99, in __call__
    res = super(Function, self).__call__(*new_args, **new_kwargs)
RRuntimeError: Error in all.equal(n.wr, sol$n.wr) : object 'n.wr' not found

ERROR:root:(1 points) Checking R('all.equal(wr.name, sol$wr.name)')[0]
ERROR:root:... Expecting: True
ERROR:root:... But got:   Traceback error
ERROR:root:Got exception:
Traceback (most recent call last):
  File "c:\Users\User\Anaconda\lib\site-packages\gradebook\score.py", line 180, in check
    result = eval(command, g)
  File "<string>", line 1, in <module>
  File "c:\Users\User\Anaconda\lib\site-packages\rpy2\robjects\__init__.py", line 246, in __call__
    res = self.eval(p)
  File "c:\Users\User\Anaconda\lib\site-packages\rpy2\robjects\functions.py", line 166, in __call__
    return super(SignatureTranslatedFunction, self).__call__(*args, **kwargs)
  File "c:\Users\User\Anaconda\lib\site-packages\rpy2\robjects\functions.py", line 99, in __call__
    res = super(Function, self).__call__(*new_args, **new_kwargs)
RRuntimeError: Error in all.equal(wr.name, sol$wr.name) : object 'wr.name' not found

ERROR:root:Traceback (most recent call last):
  File "c:\Users\User\Anaconda\lib\site-packages\gradebook\score.py", line 180, in check
    result = eval(command, g)
  File "<string>", line 1, in <module>
  File "c:\Users\User\Anaconda\lib\site-packages\rpy2\robjects\__init__.py", line 246, in __call__
    res = self.eval(p)
  File "c:\Users\User\Anaconda\lib\site-packages\rpy2\robjects\functions.py", line 166, in __call__
    return super(SignatureTranslatedFunction, self).__call__(*args, **kwargs)
  File "c:\Users\User\Anaconda\lib\site-packages\rpy2\robjects\functions.py", line 99, in __call__
    res = super(Function, self).__call__(*new_args, **new_kwargs)
RRuntimeError: Error in all.equal(wr.name, sol$wr.name) : object 'wr.name' not found

Traceback (most recent call last):
  File "c:\Users\User\Anaconda\lib\site-packages\gradebook\score.py", line 180, in check
    result = eval(command, g)
  File "<string>", line 1, in <module>
  File "c:\Users\User\Anaconda\lib\site-packages\rpy2\robjects\__init__.py", line 246, in __call__
    res = self.eval(p)
  File "c:\Users\User\Anaconda\lib\site-packages\rpy2\robjects\functions.py", line 166, in __call__
    return super(SignatureTranslatedFunction, self).__call__(*args, **kwargs)
  File "c:\Users\User\Anaconda\lib\site-packages\rpy2\robjects\functions.py", line 99, in __call__
    res = super(Function, self).__call__(*new_args, **new_kwargs)
RRuntimeError: Error in all.equal(wr.name, sol$wr.name) : object 'wr.name' not found

ERROR:root:(1 points) Checking R('all.equal(times_sec, sol$times_sec)')[0]
ERROR:root:... Expecting: True
ERROR:root:... But got:   Traceback error
ERROR:root:Got exception:
Traceback (most recent call last):
  File "c:\Users\User\Anaconda\lib\site-packages\gradebook\score.py", line 180, in check
    result = eval(command, g)
  File "<string>", line 1, in <module>
  File "c:\Users\User\Anaconda\lib\site-packages\rpy2\robjects\__init__.py", line 246, in __call__
    res = self.eval(p)
  File "c:\Users\User\Anaconda\lib\site-packages\rpy2\robjects\functions.py", line 166, in __call__
    return super(SignatureTranslatedFunction, self).__call__(*args, **kwargs)
  File "c:\Users\User\Anaconda\lib\site-packages\rpy2\robjects\functions.py", line 99, in __call__
    res = super(Function, self).__call__(*new_args, **new_kwargs)
RRuntimeError: Error in all.equal(times_sec, sol$times_sec) : 
  object 'times_sec' not found

ERROR:root:Traceback (most recent call last):
  File "c:\Users\User\Anaconda\lib\site-packages\gradebook\score.py", line 180, in check
    result = eval(command, g)
  File "<string>", line 1, in <module>
  File "c:\Users\User\Anaconda\lib\site-packages\rpy2\robjects\__init__.py", line 246, in __call__
    res = self.eval(p)
  File "c:\Users\User\Anaconda\lib\site-packages\rpy2\robjects\functions.py", line 166, in __call__
    return super(SignatureTranslatedFunction, self).__call__(*args, **kwargs)
  File "c:\Users\User\Anaconda\lib\site-packages\rpy2\robjects\functions.py", line 99, in __call__
    res = super(Function, self).__call__(*new_args, **new_kwargs)
RRuntimeError: Error in all.equal(times_sec, sol$times_sec) : 
  object 'times_sec' not found

Traceback (most recent call last):
  File "c:\Users\User\Anaconda\lib\site-packages\gradebook\score.py", line 180, in check
    result = eval(command, g)
  File "<string>", line 1, in <module>
  File "c:\Users\User\Anaconda\lib\site-packages\rpy2\robjects\__init__.py", line 246, in __call__
    res = self.eval(p)
  File "c:\Users\User\Anaconda\lib\site-packages\rpy2\robjects\functions.py", line 166, in __call__
    return super(SignatureTranslatedFunction, self).__call__(*args, **kwargs)
  File "c:\Users\User\Anaconda\lib\site-packages\rpy2\robjects\functions.py", line 99, in __call__
    res = super(Function, self).__call__(*new_args, **new_kwargs)
RRuntimeError: Error in all.equal(times_sec, sol$times_sec) : 
  object 'times_sec' not found

ERROR:root:(1 points) Checking R('all.equal(new_year, sol$new_year)')[0]
ERROR:root:... Expecting: True
ERROR:root:... But got:   Traceback error
ERROR:root:Got exception:
Traceback (most recent call last):
  File "c:\Users\User\Anaconda\lib\site-packages\gradebook\score.py", line 180, in check
    result = eval(command, g)
  File "<string>", line 1, in <module>
  File "c:\Users\User\Anaconda\lib\site-packages\rpy2\robjects\__init__.py", line 246, in __call__
    res = self.eval(p)
  File "c:\Users\User\Anaconda\lib\site-packages\rpy2\robjects\functions.py", line 166, in __call__
    return super(SignatureTranslatedFunction, self).__call__(*args, **kwargs)
  File "c:\Users\User\Anaconda\lib\site-packages\rpy2\robjects\functions.py", line 99, in __call__
    res = super(Function, self).__call__(*new_args, **new_kwargs)
RRuntimeError: Error in all.equal(new_year, sol$new_year) : object 'new_year' not found

ERROR:root:Traceback (most recent call last):
  File "c:\Users\User\Anaconda\lib\site-packages\gradebook\score.py", line 180, in check
    result = eval(command, g)
  File "<string>", line 1, in <module>
  File "c:\Users\User\Anaconda\lib\site-packages\rpy2\robjects\__init__.py", line 246, in __call__
    res = self.eval(p)
  File "c:\Users\User\Anaconda\lib\site-packages\rpy2\robjects\functions.py", line 166, in __call__
    return super(SignatureTranslatedFunction, self).__call__(*args, **kwargs)
  File "c:\Users\User\Anaconda\lib\site-packages\rpy2\robjects\functions.py", line 99, in __call__
    res = super(Function, self).__call__(*new_args, **new_kwargs)
RRuntimeError: Error in all.equal(new_year, sol$new_year) : object 'new_year' not found

Traceback (most recent call last):
  File "c:\Users\User\Anaconda\lib\site-packages\gradebook\score.py", line 180, in check
    result = eval(command, g)
  File "<string>", line 1, in <module>
  File "c:\Users\User\Anaconda\lib\site-packages\rpy2\robjects\__init__.py", line 246, in __call__
    res = self.eval(p)
  File "c:\Users\User\Anaconda\lib\site-packages\rpy2\robjects\functions.py", line 166, in __call__
    return super(SignatureTranslatedFunction, self).__call__(*args, **kwargs)
  File "c:\Users\User\Anaconda\lib\site-packages\rpy2\robjects\functions.py", line 99, in __call__
    res = super(Function, self).__call__(*new_args, **new_kwargs)
RRuntimeError: Error in all.equal(new_year, sol$new_year) : object 'new_year' not found

ERROR:root:(1 points) Checking R('all.equal(wr1500m[1:6], sol$wr1500m.1)')[0]
ERROR:root:... Expecting: True
ERROR:root:... But got:   Traceback error
ERROR:root:Got exception:
Traceback (most recent call last):
  File "c:\Users\User\Anaconda\lib\site-packages\gradebook\score.py", line 180, in check
    result = eval(command, g)
  File "<string>", line 1, in <module>
  File "c:\Users\User\Anaconda\lib\site-packages\rpy2\robjects\__init__.py", line 246, in __call__
    res = self.eval(p)
  File "c:\Users\User\Anaconda\lib\site-packages\rpy2\robjects\functions.py", line 166, in __call__
    return super(SignatureTranslatedFunction, self).__call__(*args, **kwargs)
  File "c:\Users\User\Anaconda\lib\site-packages\rpy2\robjects\functions.py", line 99, in __call__
    res = super(Function, self).__call__(*new_args, **new_kwargs)
RRuntimeError: Error in all.equal(wr1500m[1:6], sol$wr1500m.1) : 
  object 'wr1500m' not found

ERROR:root:Traceback (most recent call last):
  File "c:\Users\User\Anaconda\lib\site-packages\gradebook\score.py", line 180, in check
    result = eval(command, g)
  File "<string>", line 1, in <module>
  File "c:\Users\User\Anaconda\lib\site-packages\rpy2\robjects\__init__.py", line 246, in __call__
    res = self.eval(p)
  File "c:\Users\User\Anaconda\lib\site-packages\rpy2\robjects\functions.py", line 166, in __call__
    return super(SignatureTranslatedFunction, self).__call__(*args, **kwargs)
  File "c:\Users\User\Anaconda\lib\site-packages\rpy2\robjects\functions.py", line 99, in __call__
    res = super(Function, self).__call__(*new_args, **new_kwargs)
RRuntimeError: Error in all.equal(wr1500m[1:6], sol$wr1500m.1) : 
  object 'wr1500m' not found

Traceback (most recent call last):
  File "c:\Users\User\Anaconda\lib\site-packages\gradebook\score.py", line 180, in check
    result = eval(command, g)
  File "<string>", line 1, in <module>
  File "c:\Users\User\Anaconda\lib\site-packages\rpy2\robjects\__init__.py", line 246, in __call__
    res = self.eval(p)
  File "c:\Users\User\Anaconda\lib\site-packages\rpy2\robjects\functions.py", line 166, in __call__
    return super(SignatureTranslatedFunction, self).__call__(*args, **kwargs)
  File "c:\Users\User\Anaconda\lib\site-packages\rpy2\robjects\functions.py", line 99, in __call__
    res = super(Function, self).__call__(*new_args, **new_kwargs)
RRuntimeError: Error in all.equal(wr1500m[1:6], sol$wr1500m.1) : 
  object 'wr1500m' not found

ERROR:root:(1 points) Checking R('all.equal(wr1500m, sol$wr1500m)')[0]
ERROR:root:... Expecting: True
ERROR:root:... But got:   Traceback error
ERROR:root:Got exception:
Traceback (most recent call last):
  File "c:\Users\User\Anaconda\lib\site-packages\gradebook\score.py", line 180, in check
    result = eval(command, g)
  File "<string>", line 1, in <module>
  File "c:\Users\User\Anaconda\lib\site-packages\rpy2\robjects\__init__.py", line 246, in __call__
    res = self.eval(p)
  File "c:\Users\User\Anaconda\lib\site-packages\rpy2\robjects\functions.py", line 166, in __call__
    return super(SignatureTranslatedFunction, self).__call__(*args, **kwargs)
  File "c:\Users\User\Anaconda\lib\site-packages\rpy2\robjects\functions.py", line 99, in __call__
    res = super(Function, self).__call__(*new_args, **new_kwargs)
RRuntimeError: Error in all.equal(wr1500m, sol$wr1500m) : object 'wr1500m' not found

ERROR:root:Traceback (most recent call last):
  File "c:\Users\User\Anaconda\lib\site-packages\gradebook\score.py", line 180, in check
    result = eval(command, g)
  File "<string>", line 1, in <module>
  File "c:\Users\User\Anaconda\lib\site-packages\rpy2\robjects\__init__.py", line 246, in __call__
    res = self.eval(p)
  File "c:\Users\User\Anaconda\lib\site-packages\rpy2\robjects\functions.py", line 166, in __call__
    return super(SignatureTranslatedFunction, self).__call__(*args, **kwargs)
  File "c:\Users\User\Anaconda\lib\site-packages\rpy2\robjects\functions.py", line 99, in __call__
    res = super(Function, self).__call__(*new_args, **new_kwargs)
RRuntimeError: Error in all.equal(wr1500m, sol$wr1500m) : object 'wr1500m' not found

Traceback (most recent call last):
  File "c:\Users\User\Anaconda\lib\site-packages\gradebook\score.py", line 180, in check
    result = eval(command, g)
  File "<string>", line 1, in <module>
  File "c:\Users\User\Anaconda\lib\site-packages\rpy2\robjects\__init__.py", line 246, in __call__
    res = self.eval(p)
  File "c:\Users\User\Anaconda\lib\site-packages\rpy2\robjects\functions.py", line 166, in __call__
    return super(SignatureTranslatedFunction, self).__call__(*args, **kwargs)
  File "c:\Users\User\Anaconda\lib\site-packages\rpy2\robjects\functions.py", line 99, in __call__
    res = super(Function, self).__call__(*new_args, **new_kwargs)
RRuntimeError: Error in all.equal(wr1500m, sol$wr1500m) : object 'wr1500m' not found

ERROR:root:(1 points) Checking R('all.equal(GDP_per_person, sol$GDP_per_person)')[0]
ERROR:root:... Expecting: True
ERROR:root:... But got:   Traceback error
ERROR:root:Got exception:
Traceback (most recent call last):
  File "c:\Users\User\Anaconda\lib\site-packages\gradebook\score.py", line 180, in check
    result = eval(command, g)
  File "<string>", line 1, in <module>
  File "c:\Users\User\Anaconda\lib\site-packages\rpy2\robjects\__init__.py", line 246, in __call__
    res = self.eval(p)
  File "c:\Users\User\Anaconda\lib\site-packages\rpy2\robjects\functions.py", line 166, in __call__
    return super(SignatureTranslatedFunction, self).__call__(*args, **kwargs)
  File "c:\Users\User\Anaconda\lib\site-packages\rpy2\robjects\functions.py", line 99, in __call__
    res = super(Function, self).__call__(*new_args, **new_kwargs)
RRuntimeError: Error in all.equal(GDP_per_person, sol$GDP_per_person) : 
  object 'GDP_per_person' not found

ERROR:root:Traceback (most recent call last):
  File "c:\Users\User\Anaconda\lib\site-packages\gradebook\score.py", line 180, in check
    result = eval(command, g)
  File "<string>", line 1, in <module>
  File "c:\Users\User\Anaconda\lib\site-packages\rpy2\robjects\__init__.py", line 246, in __call__
    res = self.eval(p)
  File "c:\Users\User\Anaconda\lib\site-packages\rpy2\robjects\functions.py", line 166, in __call__
    return super(SignatureTranslatedFunction, self).__call__(*args, **kwargs)
  File "c:\Users\User\Anaconda\lib\site-packages\rpy2\robjects\functions.py", line 99, in __call__
    res = super(Function, self).__call__(*new_args, **new_kwargs)
RRuntimeError: Error in all.equal(GDP_per_person, sol$GDP_per_person) : 
  object 'GDP_per_person' not found

Traceback (most recent call last):
  File "c:\Users\User\Anaconda\lib\site-packages\gradebook\score.py", line 180, in check
    result = eval(command, g)
  File "<string>", line 1, in <module>
  File "c:\Users\User\Anaconda\lib\site-packages\rpy2\robjects\__init__.py", line 246, in __call__
    res = self.eval(p)
  File "c:\Users\User\Anaconda\lib\site-packages\rpy2\robjects\functions.py", line 166, in __call__
    return super(SignatureTranslatedFunction, self).__call__(*args, **kwargs)
  File "c:\Users\User\Anaconda\lib\site-packages\rpy2\robjects\functions.py", line 99, in __call__
    res = super(Function, self).__call__(*new_args, **new_kwargs)
RRuntimeError: Error in all.equal(GDP_per_person, sol$GDP_per_person) : 
  object 'GDP_per_person' not found

ERROR:root:(1 points) Checking R('all.equal(top5, sol$top5)')[0]
ERROR:root:... Expecting: True
ERROR:root:... But got:   Traceback error
ERROR:root:Got exception:
Traceback (most recent call last):
  File "c:\Users\User\Anaconda\lib\site-packages\gradebook\score.py", line 180, in check
    result = eval(command, g)
  File "<string>", line 1, in <module>
  File "c:\Users\User\Anaconda\lib\site-packages\rpy2\robjects\__init__.py", line 246, in __call__
    res = self.eval(p)
  File "c:\Users\User\Anaconda\lib\site-packages\rpy2\robjects\functions.py", line 166, in __call__
    return super(SignatureTranslatedFunction, self).__call__(*args, **kwargs)
  File "c:\Users\User\Anaconda\lib\site-packages\rpy2\robjects\functions.py", line 99, in __call__
    res = super(Function, self).__call__(*new_args, **new_kwargs)
RRuntimeError: Error in all.equal(top5, sol$top5) : object 'top5' not found

ERROR:root:Traceback (most recent call last):
  File "c:\Users\User\Anaconda\lib\site-packages\gradebook\score.py", line 180, in check
    result = eval(command, g)
  File "<string>", line 1, in <module>
  File "c:\Users\User\Anaconda\lib\site-packages\rpy2\robjects\__init__.py", line 246, in __call__
    res = self.eval(p)
  File "c:\Users\User\Anaconda\lib\site-packages\rpy2\robjects\functions.py", line 166, in __call__
    return super(SignatureTranslatedFunction, self).__call__(*args, **kwargs)
  File "c:\Users\User\Anaconda\lib\site-packages\rpy2\robjects\functions.py", line 99, in __call__
    res = super(Function, self).__call__(*new_args, **new_kwargs)
RRuntimeError: Error in all.equal(top5, sol$top5) : object 'top5' not found

Traceback (most recent call last):
  File "c:\Users\User\Anaconda\lib\site-packages\gradebook\score.py", line 180, in check
    result = eval(command, g)
  File "<string>", line 1, in <module>
  File "c:\Users\User\Anaconda\lib\site-packages\rpy2\robjects\__init__.py", line 246, in __call__
    res = self.eval(p)
  File "c:\Users\User\Anaconda\lib\site-packages\rpy2\robjects\functions.py", line 166, in __call__
    return super(SignatureTranslatedFunction, self).__call__(*args, **kwargs)
  File "c:\Users\User\Anaconda\lib\site-packages\rpy2\robjects\functions.py", line 99, in __call__
    res = super(Function, self).__call__(*new_args, **new_kwargs)
RRuntimeError: Error in all.equal(top5, sol$top5) : object 'top5' not found

ERROR:root:(1 points) Checking R('all.equal(wonMedal, sol$wonMedal)')[0]
ERROR:root:... Expecting: True
ERROR:root:... But got:   Traceback error
ERROR:root:Got exception:
Traceback (most recent call last):
  File "c:\Users\User\Anaconda\lib\site-packages\gradebook\score.py", line 180, in check
    result = eval(command, g)
  File "<string>", line 1, in <module>
  File "c:\Users\User\Anaconda\lib\site-packages\rpy2\robjects\__init__.py", line 246, in __call__
    res = self.eval(p)
  File "c:\Users\User\Anaconda\lib\site-packages\rpy2\robjects\functions.py", line 166, in __call__
    return super(SignatureTranslatedFunction, self).__call__(*args, **kwargs)
  File "c:\Users\User\Anaconda\lib\site-packages\rpy2\robjects\functions.py", line 99, in __call__
    res = super(Function, self).__call__(*new_args, **new_kwargs)
RRuntimeError: Error in all.equal(wonMedal, sol$wonMedal) : object 'wonMedal' not found

ERROR:root:Traceback (most recent call last):
  File "c:\Users\User\Anaconda\lib\site-packages\gradebook\score.py", line 180, in check
    result = eval(command, g)
  File "<string>", line 1, in <module>
  File "c:\Users\User\Anaconda\lib\site-packages\rpy2\robjects\__init__.py", line 246, in __call__
    res = self.eval(p)
  File "c:\Users\User\Anaconda\lib\site-packages\rpy2\robjects\functions.py", line 166, in __call__
    return super(SignatureTranslatedFunction, self).__call__(*args, **kwargs)
  File "c:\Users\User\Anaconda\lib\site-packages\rpy2\robjects\functions.py", line 99, in __call__
    res = super(Function, self).__call__(*new_args, **new_kwargs)
RRuntimeError: Error in all.equal(wonMedal, sol$wonMedal) : object 'wonMedal' not found

Traceback (most recent call last):
  File "c:\Users\User\Anaconda\lib\site-packages\gradebook\score.py", line 180, in check
    result = eval(command, g)
  File "<string>", line 1, in <module>
  File "c:\Users\User\Anaconda\lib\site-packages\rpy2\robjects\__init__.py", line 246, in __call__
    res = self.eval(p)
  File "c:\Users\User\Anaconda\lib\site-packages\rpy2\robjects\functions.py", line 166, in __call__
    return super(SignatureTranslatedFunction, self).__call__(*args, **kwargs)
  File "c:\Users\User\Anaconda\lib\site-packages\rpy2\robjects\functions.py", line 99, in __call__
    res = super(Function, self).__call__(*new_args, **new_kwargs)
RRuntimeError: Error in all.equal(wonMedal, sol$wonMedal) : object 'wonMedal' not found

ERROR:root:(1 points) Checking R('all.equal(n.athletes, sol$n.athletes)')[0]
ERROR:root:... Expecting: True
ERROR:root:... But got:   Traceback error
ERROR:root:Got exception:
Traceback (most recent call last):
  File "c:\Users\User\Anaconda\lib\site-packages\gradebook\score.py", line 180, in check
    result = eval(command, g)
  File "<string>", line 1, in <module>
  File "c:\Users\User\Anaconda\lib\site-packages\rpy2\robjects\__init__.py", line 246, in __call__
    res = self.eval(p)
  File "c:\Users\User\Anaconda\lib\site-packages\rpy2\robjects\functions.py", line 166, in __call__
    return super(SignatureTranslatedFunction, self).__call__(*args, **kwargs)
  File "c:\Users\User\Anaconda\lib\site-packages\rpy2\robjects\functions.py", line 99, in __call__
    res = super(Function, self).__call__(*new_args, **new_kwargs)
RRuntimeError: Error in all.equal(n.athletes, sol$n.athletes) : 
  object 'n.athletes' not found

ERROR:root:Traceback (most recent call last):
  File "c:\Users\User\Anaconda\lib\site-packages\gradebook\score.py", line 180, in check
    result = eval(command, g)
  File "<string>", line 1, in <module>
  File "c:\Users\User\Anaconda\lib\site-packages\rpy2\robjects\__init__.py", line 246, in __call__
    res = self.eval(p)
  File "c:\Users\User\Anaconda\lib\site-packages\rpy2\robjects\functions.py", line 166, in __call__
    return super(SignatureTranslatedFunction, self).__call__(*args, **kwargs)
  File "c:\Users\User\Anaconda\lib\site-packages\rpy2\robjects\functions.py", line 99, in __call__
    res = super(Function, self).__call__(*new_args, **new_kwargs)
RRuntimeError: Error in all.equal(n.athletes, sol$n.athletes) : 
  object 'n.athletes' not found

Traceback (most recent call last):
  File "c:\Users\User\Anaconda\lib\site-packages\gradebook\score.py", line 180, in check
    result = eval(command, g)
  File "<string>", line 1, in <module>
  File "c:\Users\User\Anaconda\lib\site-packages\rpy2\robjects\__init__.py", line 246, in __call__
    res = self.eval(p)
  File "c:\Users\User\Anaconda\lib\site-packages\rpy2\robjects\functions.py", line 166, in __call__
    return super(SignatureTranslatedFunction, self).__call__(*args, **kwargs)
  File "c:\Users\User\Anaconda\lib\site-packages\rpy2\robjects\functions.py", line 99, in __call__
    res = super(Function, self).__call__(*new_args, **new_kwargs)
RRuntimeError: Error in all.equal(n.athletes, sol$n.athletes) : 
  object 'n.athletes' not found

ERROR:root:(1 points) Checking R('all.equal(frac.women, sol$frac.women)')[0]
ERROR:root:... Expecting: True
ERROR:root:... But got:   Traceback error
ERROR:root:Got exception:
Traceback (most recent call last):
  File "c:\Users\User\Anaconda\lib\site-packages\gradebook\score.py", line 180, in check
    result = eval(command, g)
  File "<string>", line 1, in <module>
  File "c:\Users\User\Anaconda\lib\site-packages\rpy2\robjects\__init__.py", line 246, in __call__
    res = self.eval(p)
  File "c:\Users\User\Anaconda\lib\site-packages\rpy2\robjects\functions.py", line 166, in __call__
    return super(SignatureTranslatedFunction, self).__call__(*args, **kwargs)
  File "c:\Users\User\Anaconda\lib\site-packages\rpy2\robjects\functions.py", line 99, in __call__
    res = super(Function, self).__call__(*new_args, **new_kwargs)
RRuntimeError: Error in all.equal(frac.women, sol$frac.women) : 
  object 'frac.women' not found

ERROR:root:Traceback (most recent call last):
  File "c:\Users\User\Anaconda\lib\site-packages\gradebook\score.py", line 180, in check
    result = eval(command, g)
  File "<string>", line 1, in <module>
  File "c:\Users\User\Anaconda\lib\site-packages\rpy2\robjects\__init__.py", line 246, in __call__
    res = self.eval(p)
  File "c:\Users\User\Anaconda\lib\site-packages\rpy2\robjects\functions.py", line 166, in __call__
    return super(SignatureTranslatedFunction, self).__call__(*args, **kwargs)
  File "c:\Users\User\Anaconda\lib\site-packages\rpy2\robjects\functions.py", line 99, in __call__
    res = super(Function, self).__call__(*new_args, **new_kwargs)
RRuntimeError: Error in all.equal(frac.women, sol$frac.women) : 
  object 'frac.women' not found

Traceback (most recent call last):
  File "c:\Users\User\Anaconda\lib\site-packages\gradebook\score.py", line 180, in check
    result = eval(command, g)
  File "<string>", line 1, in <module>
  File "c:\Users\User\Anaconda\lib\site-packages\rpy2\robjects\__init__.py", line 246, in __call__
    res = self.eval(p)
  File "c:\Users\User\Anaconda\lib\site-packages\rpy2\robjects\functions.py", line 166, in __call__
    return super(SignatureTranslatedFunction, self).__call__(*args, **kwargs)
  File "c:\Users\User\Anaconda\lib\site-packages\rpy2\robjects\functions.py", line 99, in __call__
    res = super(Function, self).__call__(*new_args, **new_kwargs)
RRuntimeError: Error in all.equal(frac.women, sol$frac.women) : 
  object 'frac.women' not found

ERROR:root:(1 points) Checking R('all.equal(n.sports, sol$n.sports)')[0]
ERROR:root:... Expecting: True
ERROR:root:... But got:   Traceback error
ERROR:root:Got exception:
Traceback (most recent call last):
  File "c:\Users\User\Anaconda\lib\site-packages\gradebook\score.py", line 180, in check
    result = eval(command, g)
  File "<string>", line 1, in <module>
  File "c:\Users\User\Anaconda\lib\site-packages\rpy2\robjects\__init__.py", line 246, in __call__
    res = self.eval(p)
  File "c:\Users\User\Anaconda\lib\site-packages\rpy2\robjects\functions.py", line 166, in __call__
    return super(SignatureTranslatedFunction, self).__call__(*args, **kwargs)
  File "c:\Users\User\Anaconda\lib\site-packages\rpy2\robjects\functions.py", line 99, in __call__
    res = super(Function, self).__call__(*new_args, **new_kwargs)
RRuntimeError: Error in all.equal(n.sports, sol$n.sports) : object 'n.sports' not found

ERROR:root:Traceback (most recent call last):
  File "c:\Users\User\Anaconda\lib\site-packages\gradebook\score.py", line 180, in check
    result = eval(command, g)
  File "<string>", line 1, in <module>
  File "c:\Users\User\Anaconda\lib\site-packages\rpy2\robjects\__init__.py", line 246, in __call__
    res = self.eval(p)
  File "c:\Users\User\Anaconda\lib\site-packages\rpy2\robjects\functions.py", line 166, in __call__
    return super(SignatureTranslatedFunction, self).__call__(*args, **kwargs)
  File "c:\Users\User\Anaconda\lib\site-packages\rpy2\robjects\functions.py", line 99, in __call__
    res = super(Function, self).__call__(*new_args, **new_kwargs)
RRuntimeError: Error in all.equal(n.sports, sol$n.sports) : object 'n.sports' not found

Traceback (most recent call last):
  File "c:\Users\User\Anaconda\lib\site-packages\gradebook\score.py", line 180, in check
    result = eval(command, g)
  File "<string>", line 1, in <module>
  File "c:\Users\User\Anaconda\lib\site-packages\rpy2\robjects\__init__.py", line 246, in __call__
    res = self.eval(p)
  File "c:\Users\User\Anaconda\lib\site-packages\rpy2\robjects\functions.py", line 166, in __call__
    return super(SignatureTranslatedFunction, self).__call__(*args, **kwargs)
  File "c:\Users\User\Anaconda\lib\site-packages\rpy2\robjects\functions.py", line 99, in __call__
    res = super(Function, self).__call__(*new_args, **new_kwargs)
RRuntimeError: Error in all.equal(n.sports, sol$n.sports) : object 'n.sports' not found

ERROR:root:(1 points) Checking R('all.equal(athTab, sol$athTab)')[0]
ERROR:root:... Expecting: True
ERROR:root:... But got:   Traceback error
ERROR:root:Got exception:
Traceback (most recent call last):
  File "c:\Users\User\Anaconda\lib\site-packages\gradebook\score.py", line 180, in check
    result = eval(command, g)
  File "<string>", line 1, in <module>
  File "c:\Users\User\Anaconda\lib\site-packages\rpy2\robjects\__init__.py", line 246, in __call__
    res = self.eval(p)
  File "c:\Users\User\Anaconda\lib\site-packages\rpy2\robjects\functions.py", line 166, in __call__
    return super(SignatureTranslatedFunction, self).__call__(*args, **kwargs)
  File "c:\Users\User\Anaconda\lib\site-packages\rpy2\robjects\functions.py", line 99, in __call__
    res = super(Function, self).__call__(*new_args, **new_kwargs)
RRuntimeError: Error in all.equal(athTab, sol$athTab) : object 'athTab' not found

ERROR:root:Traceback (most recent call last):
  File "c:\Users\User\Anaconda\lib\site-packages\gradebook\score.py", line 180, in check
    result = eval(command, g)
  File "<string>", line 1, in <module>
  File "c:\Users\User\Anaconda\lib\site-packages\rpy2\robjects\__init__.py", line 246, in __call__
    res = self.eval(p)
  File "c:\Users\User\Anaconda\lib\site-packages\rpy2\robjects\functions.py", line 166, in __call__
    return super(SignatureTranslatedFunction, self).__call__(*args, **kwargs)
  File "c:\Users\User\Anaconda\lib\site-packages\rpy2\robjects\functions.py", line 99, in __call__
    res = super(Function, self).__call__(*new_args, **new_kwargs)
RRuntimeError: Error in all.equal(athTab, sol$athTab) : object 'athTab' not found

Traceback (most recent call last):
  File "c:\Users\User\Anaconda\lib\site-packages\gradebook\score.py", line 180, in check
    result = eval(command, g)
  File "<string>", line 1, in <module>
  File "c:\Users\User\Anaconda\lib\site-packages\rpy2\robjects\__init__.py", line 246, in __call__
    res = self.eval(p)
  File "c:\Users\User\Anaconda\lib\site-packages\rpy2\robjects\functions.py", line 166, in __call__
    return super(SignatureTranslatedFunction, self).__call__(*args, **kwargs)
  File "c:\Users\User\Anaconda\lib\site-packages\rpy2\robjects\functions.py", line 99, in __call__
    res = super(Function, self).__call__(*new_args, **new_kwargs)
RRuntimeError: Error in all.equal(athTab, sol$athTab) : object 'athTab' not found

ERROR:root:(1 points) Checking R('all.equal(set.beside, sol$set.beside)')[0]
ERROR:root:... Expecting: True
ERROR:root:... But got:   Traceback error
ERROR:root:Got exception:
Traceback (most recent call last):
  File "c:\Users\User\Anaconda\lib\site-packages\gradebook\score.py", line 180, in check
    result = eval(command, g)
  File "<string>", line 1, in <module>
  File "c:\Users\User\Anaconda\lib\site-packages\rpy2\robjects\__init__.py", line 246, in __call__
    res = self.eval(p)
  File "c:\Users\User\Anaconda\lib\site-packages\rpy2\robjects\functions.py", line 166, in __call__
    return super(SignatureTranslatedFunction, self).__call__(*args, **kwargs)
  File "c:\Users\User\Anaconda\lib\site-packages\rpy2\robjects\functions.py", line 99, in __call__
    res = super(Function, self).__call__(*new_args, **new_kwargs)
RRuntimeError: Error in all.equal(set.beside, sol$set.beside) : 
  object 'set.beside' not found

ERROR:root:Traceback (most recent call last):
  File "c:\Users\User\Anaconda\lib\site-packages\gradebook\score.py", line 180, in check
    result = eval(command, g)
  File "<string>", line 1, in <module>
  File "c:\Users\User\Anaconda\lib\site-packages\rpy2\robjects\__init__.py", line 246, in __call__
    res = self.eval(p)
  File "c:\Users\User\Anaconda\lib\site-packages\rpy2\robjects\functions.py", line 166, in __call__
    return super(SignatureTranslatedFunction, self).__call__(*args, **kwargs)
  File "c:\Users\User\Anaconda\lib\site-packages\rpy2\robjects\functions.py", line 99, in __call__
    res = super(Function, self).__call__(*new_args, **new_kwargs)
RRuntimeError: Error in all.equal(set.beside, sol$set.beside) : 
  object 'set.beside' not found

Traceback (most recent call last):
  File "c:\Users\User\Anaconda\lib\site-packages\gradebook\score.py", line 180, in check
    result = eval(command, g)
  File "<string>", line 1, in <module>
  File "c:\Users\User\Anaconda\lib\site-packages\rpy2\robjects\__init__.py", line 246, in __call__
    res = self.eval(p)
  File "c:\Users\User\Anaconda\lib\site-packages\rpy2\robjects\functions.py", line 166, in __call__
    return super(SignatureTranslatedFunction, self).__call__(*args, **kwargs)
  File "c:\Users\User\Anaconda\lib\site-packages\rpy2\robjects\functions.py", line 99, in __call__
    res = super(Function, self).__call__(*new_args, **new_kwargs)
RRuntimeError: Error in all.equal(set.beside, sol$set.beside) : 
  object 'set.beside' not found

ERROR:root:(1 points) Checking R('all.equal(athTab2, sol$athTab2)')[0]
ERROR:root:... Expecting: True
ERROR:root:... But got:   Traceback error
ERROR:root:Got exception:
Traceback (most recent call last):
  File "c:\Users\User\Anaconda\lib\site-packages\gradebook\score.py", line 180, in check
    result = eval(command, g)
  File "<string>", line 1, in <module>
  File "c:\Users\User\Anaconda\lib\site-packages\rpy2\robjects\__init__.py", line 246, in __call__
    res = self.eval(p)
  File "c:\Users\User\Anaconda\lib\site-packages\rpy2\robjects\functions.py", line 166, in __call__
    return super(SignatureTranslatedFunction, self).__call__(*args, **kwargs)
  File "c:\Users\User\Anaconda\lib\site-packages\rpy2\robjects\functions.py", line 99, in __call__
    res = super(Function, self).__call__(*new_args, **new_kwargs)
RRuntimeError: Error in all.equal(athTab2, sol$athTab2) : object 'athTab2' not found

ERROR:root:Traceback (most recent call last):
  File "c:\Users\User\Anaconda\lib\site-packages\gradebook\score.py", line 180, in check
    result = eval(command, g)
  File "<string>", line 1, in <module>
  File "c:\Users\User\Anaconda\lib\site-packages\rpy2\robjects\__init__.py", line 246, in __call__
    res = self.eval(p)
  File "c:\Users\User\Anaconda\lib\site-packages\rpy2\robjects\functions.py", line 166, in __call__
    return super(SignatureTranslatedFunction, self).__call__(*args, **kwargs)
  File "c:\Users\User\Anaconda\lib\site-packages\rpy2\robjects\functions.py", line 99, in __call__
    res = super(Function, self).__call__(*new_args, **new_kwargs)
RRuntimeError: Error in all.equal(athTab2, sol$athTab2) : object 'athTab2' not found

Traceback (most recent call last):
  File "c:\Users\User\Anaconda\lib\site-packages\gradebook\score.py", line 180, in check
    result = eval(command, g)
  File "<string>", line 1, in <module>
  File "c:\Users\User\Anaconda\lib\site-packages\rpy2\robjects\__init__.py", line 246, in __call__
    res = self.eval(p)
  File "c:\Users\User\Anaconda\lib\site-packages\rpy2\robjects\functions.py", line 166, in __call__
    return super(SignatureTranslatedFunction, self).__call__(*args, **kwargs)
  File "c:\Users\User\Anaconda\lib\site-packages\rpy2\robjects\functions.py", line 99, in __call__
    res = super(Function, self).__call__(*new_args, **new_kwargs)
RRuntimeError: Error in all.equal(athTab2, sol$athTab2) : object 'athTab2' not found

ERROR:root:(1 points) Checking R('all.equal(orderSport, sol$orderSport)')[0]
ERROR:root:... Expecting: True
ERROR:root:... But got:   Traceback error
ERROR:root:Got exception:
Traceback (most recent call last):
  File "c:\Users\User\Anaconda\lib\site-packages\gradebook\score.py", line 180, in check
    result = eval(command, g)
  File "<string>", line 1, in <module>
  File "c:\Users\User\Anaconda\lib\site-packages\rpy2\robjects\__init__.py", line 246, in __call__
    res = self.eval(p)
  File "c:\Users\User\Anaconda\lib\site-packages\rpy2\robjects\functions.py", line 166, in __call__
    return super(SignatureTranslatedFunction, self).__call__(*args, **kwargs)
  File "c:\Users\User\Anaconda\lib\site-packages\rpy2\robjects\functions.py", line 99, in __call__
    res = super(Function, self).__call__(*new_args, **new_kwargs)
RRuntimeError: Error in all.equal(orderSport, sol$orderSport) : 
  object 'orderSport' not found

ERROR:root:Traceback (most recent call last):
  File "c:\Users\User\Anaconda\lib\site-packages\gradebook\score.py", line 180, in check
    result = eval(command, g)
  File "<string>", line 1, in <module>
  File "c:\Users\User\Anaconda\lib\site-packages\rpy2\robjects\__init__.py", line 246, in __call__
    res = self.eval(p)
  File "c:\Users\User\Anaconda\lib\site-packages\rpy2\robjects\functions.py", line 166, in __call__
    return super(SignatureTranslatedFunction, self).__call__(*args, **kwargs)
  File "c:\Users\User\Anaconda\lib\site-packages\rpy2\robjects\functions.py", line 99, in __call__
    res = super(Function, self).__call__(*new_args, **new_kwargs)
RRuntimeError: Error in all.equal(orderSport, sol$orderSport) : 
  object 'orderSport' not found

Traceback (most recent call last):
  File "c:\Users\User\Anaconda\lib\site-packages\gradebook\score.py", line 180, in check
    result = eval(command, g)
  File "<string>", line 1, in <module>
  File "c:\Users\User\Anaconda\lib\site-packages\rpy2\robjects\__init__.py", line 246, in __call__
    res = self.eval(p)
  File "c:\Users\User\Anaconda\lib\site-packages\rpy2\robjects\functions.py", line 166, in __call__
    return super(SignatureTranslatedFunction, self).__call__(*args, **kwargs)
  File "c:\Users\User\Anaconda\lib\site-packages\rpy2\robjects\functions.py", line 99, in __call__
    res = super(Function, self).__call__(*new_args, **new_kwargs)
RRuntimeError: Error in all.equal(orderSport, sol$orderSport) : 
  object 'orderSport' not found

ERROR:root:(1 points) Checking Does the final plot have at least the elements in a basic plot?
ERROR:root:... Expecting: False
ERROR:root:... But got:   n
ERROR:root:(1 points) Checking Does the final plot contain a main title, an x-label and a y-label?
ERROR:root:... Expecting: False
ERROR:root:... But got:   n
ERROR:root:(1 points) Checking Does the final plot have the extension of line?
ERROR:root:... Expecting: False
ERROR:root:... But got:   n
ERROR:root:(1 points) Checking Are there two vertical lines with text names?
ERROR:root:... Expecting: False
ERROR:root:... But got:   n
ERROR:root:(1 points) Checking Are the vertical lines grey?
ERROR:root:... Expecting: False
ERROR:root:... But got:   n
ERROR:root:(1 points) Checking Is the plot not too cluttered?
ERROR:root:... Expecting: False
ERROR:root:... But got:   n
ERROR:root:(1 points) Checking Are there labels in the plot?
ERROR:root:... Expecting: False
ERROR:root:... But got:   n
ERROR:root:(1 points) Checking Are there circles and points in the plot?
ERROR:root:... Expecting: False
ERROR:root:... But got:   n
ERROR:root:(1 points) Checking Are there five labelled circles in the plot?
ERROR:root:... Expecting: False
ERROR:root:... But got:   n
ERROR:root:(1 points) Checking Does the basic plot look fine?
ERROR:root:... Expecting: False
ERROR:root:... But got:   n
ERROR:root:(1 points) Checking Does the plot look good?
ERROR:root:... Expecting: False
ERROR:root:... But got:   n
ERROR:root:(1 points) Checking Are the circles of decent size?
ERROR:root:... Expecting: False
ERROR:root:... But got:   n
ERROR:root:(1 points) Checking Are the colors reasonable?
ERROR:root:... Expecting: False
ERROR:root:... But got:   n
ERROR:root:(1 points) Checking Are the bars side-by-side?
ERROR:root:... Expecting: False
ERROR:root:... But got:   n
ERROR:root:(1 points) Checking Are the labels rotated?
ERROR:root:... Expecting: False
ERROR:root:... But got:   n
ERROR:root:(1 points) Checking Does the title and the plot look okay?
ERROR:root:... Expecting: False
ERROR:root:... But got:   n
INFO:root:You got a 0 out of 32.
